Workbook

Sheet 알루미늄 부품
A1: Pygmalion 알루미늄 부품 — 3D 프린트 실측 질량 조사
A2: 노란 칸(E열)에만 입력하세요. 저울로 잰 값을 그램 숫자로 — 예: 78.4 · D열은 CAD 형상에 알루미늄 6061(2.70 g/cm³)을 적용한 값입니다.
A3: 출처: Fusion 360 문서 260819_HumanMesh_wUpper_OMAKASE v4, 살아있는(표시된) 바디 81개 · 사진은 각 바디의 메시를 단독 렌더한 것
A4: E열 기입값은 출력물 사진의 손글씨를 읽어 CAD 부품에 대조한 것 — 초록=확실 · 노랑=보통(A/B 짝 미확정) · 주황=불확실(실물 대조 필요). F열이 46 %를 넘으면 빨강: PLA(1.24)/알루(2.70) 물리 상한 초과 = 오독 또는 오배정.
A5: 소속 링크 | B5: 사진 | C5: 파츠명 | D5: 질량 (알루 6061, g) | E5: 측정 질량 (3D 프린트, g) | F5: 측정/CAD | G5: 비고
A6: (미배정) | C6: NoSim_2-RSU-Originator / Body1 | D6: 54.69 | F6: =IF(E6="","",E6/D6) | G6: 설계 참조용 (NoSim) — 실물 아님
A7: (미배정) | C7: NoSim_2-RSU-Originator / Body2 | D7: 42.59 | F7: =IF(E7="","",E7/D7) | G7: 설계 참조용 (NoSim) — 실물 아님
A8: ankle_pitch_link | C8: Ankle2Feet / AnkleUniversalJointCore | D8: 66.99 | F8: =IF(E8="","",E8/D8)
A9: arm_link (팔) | C9: DR2020-375L-ArmR / DR2020-375L (1) | D9: 293.43 | F9: =IF(E9="","",E9/D9) | G9: 2020 알루미늄 압출 프로파일 (구매품)
A10: base_link (골반) | C10: CenterParts / BaseLink_Bottom_A | D10: 195.79 | F10: =IF(E10="","",E10/D10)
A11: base_link (골반) | C11: CenterParts / BaseLink_Bottom_B | D11: 195.28 | F11: =IF(E11="","",E11/D11)
A12: base_link (골반) | C12: CenterParts / Baselink_toWaistYaw | D12: 192.39 | F12: =IF(E12="","",E12/D12)
A13: base_link (골반) | C13: CenterParts / Baselink_Connect_Fr | D13: 100.22 | F13: =IF(E13="","",E13/D13)
A14: base_link (골반) | C14: CenterParts / Baselink_Connect_Ba | D14: 100.22 | F14: =IF(E14="","",E14/D14)
A15: foot_link (발) | C15: Ankle2Feet / FEET | D15: 616.53 | E15: 119 | F15: =IF(E15="","",E15/D15) | G15: 사진6,7,10 '119 (114? 124?)' · 불확실 · 발판. 세 사진 모두 11x로 읽히나 마지막 자리 불명. 비율 0.19 - 두꺼운 판이라 저충전 출력 가능성
A16: foot_link (발) | C16: Ankle2Feet / AnkleFeetPillowAB | D16: 105.16 | F16: =IF(E16="","",E16/D16)
A17: foot_link (발) | C17: Ankle2Feet / AnkleFeetPillowA | D17: 40.88 | F17: =IF(E17="","",E17/D17)
A18: foot_link (발) | C18: Ankle2Feet / AnkleFeetPillowB | D18: 40.88 | F18: =IF(E18="","",E18/D18)
A19: foot_link (발) | C19: Ankle2Feet / Ankle_Stopper_Roll | D19: 26.55 | F19: =IF(E19="","",E19/D19)
A20: foot_link (발) | C20: Flange / 20deg_flangeA | D20: 0.32 | F20: =IF(E20="","",E20/D20)
A21: foot_link (발) | C21: Flange / 20deg_flangeB | D21: 0.32 | F21: =IF(E21="","",E21/D21)
A22: foot_link (발) | C22: Flange(Mirror) / 20deg_flangeA | D22: 0.32 | F22: =IF(E22="","",E22/D22)
A23: foot_link (발) | C23: Flange(Mirror) / 20deg_flangeB | D23: 0.32 | F23: =IF(E23="","",E23/D23)
A24: hip_pitch_link | C24: HipPitch2Roll / HipPitchRotor | D24: 199.2 | E24: 84.5 | F24: =IF(E24="","",E24/D24) | G24: 사진4,9 '84.5 / '8ㅂ'' · 불확실 · 대안: HipRoll2Yaw_Mount면 0.51로 물리 불가 · 사진9에서는 X-래티스 블록 위에 적힌 것으로 보여 배정이 틀렸을 수 있음. 그러나 84.5 g를 PLA 상한(0.46) 안에서 낼 수 있는 힙 부품은 CAD 199 g인 이 부품뿐
A25: hip_pitch_link | C25: HipPitch2Roll / HipPitch2Roll_B | D25: 147.98 | E25: 53 | F25: =IF(E25="","",E25/D25) | G25: 사진6 '53.0 (23.0?)' · 불확실 · 대안: HipPitch2Roll_A (128 g, 0.41) · 사진6 좌상단 힙 피치 D판. 비율 0.36
A26: hip_pitch_link | C26: HipPitch2Roll / HipPitch2Roll_A | D26: 128.16 | F26: =IF(E26="","",E26/D26)
A27: hip_pitch_link | C27: HipPitch2Roll / HipPitchFlange | D27: 106.97 | F27: =IF(E27="","",E27/D27)
A28: hip_roll_link | C28: HipRoll2Yaw / HipRoll2YawA | D28: 165.46 | E28: 57.2 | F28: =IF(E28="","",E28/D28) | G28: 사진2,4 '57.2 (두 사진 모두)' · 보통 · 대안: HipRoll2YawB (136 g) · 요 모터 바로 위 둥근 판, 상단 6볼트 로터 패턴. 사진 2와 4에서 같은 값 확인
A29: hip_roll_link | C29: HipRoll2Yaw / HipRoll2Yaw_Mount | D29: 164.61 | E29: 67.3 | F29: =IF(E29="","",E29/D29) | G29: 사진3,4,8 '67 / 67.3' · 보통 · 대안: HipPitch2Roll_B (148 g, 비율 0.45 - 상한 직전) · 요 모터 둘레 칼라(사진8 '67.3')가 사진3의 '67'과 같은 부품 - 소수점 보정
A30: hip_roll_link | C30: HipRoll2Yaw / HipRoll2YawB | D30: 135.5 | F30: =IF(E30="","",E30/D30)
A31: hip_roll_link | C31: HipRoll2Yaw / Body4 | D31: 39.27 | E31: 13.4 | F31: =IF(E31="","",E31/D31) | G31: 사진10 '13.4' · 보통 · 힙 요 모터 위 소형 X-래티스 블록(사진10 맨 위). 비율 0.34
A32: shin/foot (푸시로드) | C32: Ankle2Feet / Arm_A | D32: 54.76 | F32: =IF(E32="","",E32/D32)
A33: shin/foot (푸시로드) | C33: Ankle2Feet / AnkleBraceA | D33: 40.54 | F33: =IF(E33="","",E33/D33)
A34: shin/foot (푸시로드) | C34: Ankle2Feet / AnkleBraceB | D34: 40.54 | F34: =IF(E34="","",E34/D34)
A35: shin_link (정강이) | C35: Ankle2Feet / KneeB2AnkleB | D35: 171.84 | F35: =IF(E35="","",E35/D35)
A36: shin_link (정강이) | C36: Ankle2Feet / KneeB2AnkleA | D36: 168.52 | E36: 36.9 | F36: =IF(E36="","",E36/D36) | G36: 사진7 '36.9 (56.9?)' · 불확실 · 대안: KneeB2AnkleB (172 g) · 무릎→발목 긴 트러스판. 36.9면 비율 0.22로 다른 부품보다 낮음(충전율 차이 가능) - 56.9면 0.34. 3/5 판독 재확인
A37: shin_link (정강이) | C37: Knee2Ankle / Knee2Ankle_RotorSide_1 | D37: 161.35 | E37: 61.2 | F37: =IF(E37="","",E37/D37) | G37: 사진1 '61.2' · 보통 · D형 판, 중앙 베어링 둘레 8볼트(로터 체결)
A38: shin_link (정강이) | C38: Knee2Ankle / Knee2Ankle_IdleSide_1 | D38: 130.53 | F38: =IF(E38="","",E38/D38)
A39: shin_link (정강이) | C39: Knee2Ankle / Knee2Ankle_RotorSide_2 | D39: 128.76 | E39: 39.2 | F39: =IF(E39="","",E39/D39) | G39: 사진1 '39.2' · 보통 · 61.2 판 아래 X-래티스 판
A40: shin_link (정강이) | C40: Knee2Ankle / Knee2Ankle_IdleSide_2 | D40: 123.63 | E40: 41.1 | F40: =IF(E40="","",E40/D40) | G40: 사진5 '41.1 (91.1?)' · 불확실 · 대안: 91.1이면 Yaw2KneePlateB(297 g, 비율 0.31) · 반대편 X-래티스 판. 첫 글자가 4인지 9인지 불확실
...

Sheet 링크별 집계
A1: 링크별 합계 — E열에 측정값을 넣는 대로 자동으로 채워집니다
A3: 소속 링크 | B3: 부품 수 | C3: CAD 알루 질량 (g) | D3: 측정 질량 합 (g) | E3: 측정 완료 수
A4: (미배정) | B4: =COUNTIF('알루미늄 부품'!$A$6:$A$86,A4) | C4: =SUMIF('알루미늄 부품'!$A$6:$A$86,A4,'알루미늄 부품'!$D$6:$D$86) | D4: =SUMIF('알루미늄 부품'!$A$6:$A$86,A4,'알루미늄 부품'!$E$6:$E$86) | E4: =COUNTIFS('알루미늄 부품'!$A$6:$A$86,A4,'알루미늄 부품'!$E$6:$E$86,"<>")
A5: ankle_pitch_link | B5: =COUNTIF('알루미늄 부품'!$A$6:$A$86,A5) | C5: =SUMIF('알루미늄 부품'!$A$6:$A$86,A5,'알루미늄 부품'!$D$6:$D$86) | D5: =SUMIF('알루미늄 부품'!$A$6:$A$86,A5,'알루미늄 부품'!$E$6:$E$86) | E5: =COUNTIFS('알루미늄 부품'!$A$6:$A$86,A5,'알루미늄 부품'!$E$6:$E$86,"<>")
A6: arm_link (팔) | B6: =COUNTIF('알루미늄 부품'!$A$6:$A$86,A6) | C6: =SUMIF('알루미늄 부품'!$A$6:$A$86,A6,'알루미늄 부품'!$D$6:$D$86) | D6: =SUMIF('알루미늄 부품'!$A$6:$A$86,A6,'알루미늄 부품'!$E$6:$E$86) | E6: =COUNTIFS('알루미늄 부품'!$A$6:$A$86,A6,'알루미늄 부품'!$E$6:$E$86,"<>")
A7: base_link (골반) | B7: =COUNTIF('알루미늄 부품'!$A$6:$A$86,A7) | C7: =SUMIF('알루미늄 부품'!$A$6:$A$86,A7,'알루미늄 부품'!$D$6:$D$86) | D7: =SUMIF('알루미늄 부품'!$A$6:$A$86,A7,'알루미늄 부품'!$E$6:$E$86) | E7: =COUNTIFS('알루미늄 부품'!$A$6:$A$86,A7,'알루미늄 부품'!$E$6:$E$86,"<>")
A8: foot_link (발) | B8: =COUNTIF('알루미늄 부품'!$A$6:$A$86,A8) | C8: =SUMIF('알루미늄 부품'!$A$6:$A$86,A8,'알루미늄 부품'!$D$6:$D$86) | D8: =SUMIF('알루미늄 부품'!$A$6:$A$86,A8,'알루미늄 부품'!$E$6:$E$86) | E8: =COUNTIFS('알루미늄 부품'!$A$6:$A$86,A8,'알루미늄 부품'!$E$6:$E$86,"<>")
A9: hip_pitch_link | B9: =COUNTIF('알루미늄 부품'!$A$6:$A$86,A9) | C9: =SUMIF('알루미늄 부품'!$A$6:$A$86,A9,'알루미늄 부품'!$D$6:$D$86) | D9: =SUMIF('알루미늄 부품'!$A$6:$A$86,A9,'알루미늄 부품'!$E$6:$E$86) | E9: =COUNTIFS('알루미늄 부품'!$A$6:$A$86,A9,'알루미늄 부품'!$E$6:$E$86,"<>")
A10: hip_roll_link | B10: =COUNTIF('알루미늄 부품'!$A$6:$A$86,A10) | C10: =SUMIF('알루미늄 부품'!$A$6:$A$86,A10,'알루미늄 부품'!$D$6:$D$86) | D10: =SUMIF('알루미늄 부품'!$A$6:$A$86,A10,'알루미늄 부품'!$E$6:$E$86) | E10: =COUNTIFS('알루미늄 부품'!$A$6:$A$86,A10,'알루미늄 부품'!$E$6:$E$86,"<>")
A11: shin/foot (푸시로드) | B11: =COUNTIF('알루미늄 부품'!$A$6:$A$86,A11) | C11: =SUMIF('알루미늄 부품'!$A$6:$A$86,A11,'알루미늄 부품'!$D$6:$D$86) | D11: =SUMIF('알루미늄 부품'!$A$6:$A$86,A11,'알루미늄 부품'!$E$6:$E$86) | E11: =COUNTIFS('알루미늄 부품'!$A$6:$A$86,A11,'알루미늄 부품'!$E$6:$E$86,"<>")
A12: shin_link (정강이) | B12: =COUNTIF('알루미늄 부품'!$A$6:$A$86,A12) | C12: =SUMIF('알루미늄 부품'!$A$6:$A$86,A12,'알루미늄 부품'!$D$6:$D$86) | D12: =SUMIF('알루미늄 부품'!$A$6:$A$86,A12,'알루미늄 부품'!$E$6:$E$86) | E12: =COUNTIFS('알루미늄 부품'!$A$6:$A$86,A12,'알루미늄 부품'!$E$6:$E$86,"<>")
A13: shoulder_pitch_link | B13: =COUNTIF('알루미늄 부품'!$A$6:$A$86,A13) | C13: =SUMIF('알루미늄 부품'!$A$6:$A$86,A13,'알루미늄 부품'!$D$6:$D$86) | D13: =SUMIF('알루미늄 부품'!$A$6:$A$86,A13,'알루미늄 부품'!$E$6:$E$86) | E13: =COUNTIFS('알루미늄 부품'!$A$6:$A$86,A13,'알루미늄 부품'!$E$6:$E$86,"<>")
A14: thigh_link (허벅지) | B14: =COUNTIF('알루미늄 부품'!$A$6:$A$86,A14) | C14: =SUMIF('알루미늄 부품'!$A$6:$A$86,A14,'알루미늄 부품'!$D$6:$D$86) | D14: =SUMIF('알루미늄 부품'!$A$6:$A$86,A14,'알루미늄 부품'!$E$6:$E$86) | E14: =COUNTIFS('알루미늄 부품'!$A$6:$A$86,A14,'알루미늄 부품'!$E$6:$E$86,"<>")
A15: torso_link (몸통) | B15: =COUNTIF('알루미늄 부품'!$A$6:$A$86,A15) | C15: =SUMIF('알루미늄 부품'!$A$6:$A$86,A15,'알루미늄 부품'!$D$6:$D$86) | D15: =SUMIF('알루미늄 부품'!$A$6:$A$86,A15,'알루미늄 부품'!$E$6:$E$86) | E15: =COUNTIFS('알루미늄 부품'!$A$6:$A$86,A15,'알루미늄 부품'!$E$6:$E$86,"<>")
A16: 합계 | B16: =SUM(B4:B15) | C16: =SUM(C4:C15) | D16: =SUM(D4:D15) | E16: =SUM(E4:E15)
